Workbook
Name _Hlk126580657: 'Registru unic-CLIENTI'!#REF!
Name Slicer_CUSTOMER: #N/A
Name Slicer_CUSTOMER1: #N/A
Name Slicer_CUSTOMER11: #N/A
Name Slicer_CUSTOMER12: #N/A
Name Slicer_CUSTOMER2: #N/A
Name Slicer_CUSTOMER21: #N/A
Name Slicer_Month: #N/A
Name Slicer_Month11: #N/A
Name Slicer_Months__Dată_de_livrare: #N/A
Name Slicer_Months__Dată_de_livrare1: #N/A
Name Slicer_Order_Finished_YES_NO: #N/A
Name Slicer_Part_Number: #N/A
Name Slicer_Part_Number1: #N/A
Name Slicer_Part_Number2: #N/A
Name Slicer_Product_Family: #N/A
Name Slicer_Product_Family1: #N/A
Name Slicer_Product_Family2: #N/A
Name Slicer_Product_Family3: #N/A
Name Slicer_Product_Family4: #N/A
Name Slicer_YEAR: #N/A
Name Slicer_YEAR11: #N/A
Name Slicer_Years__ETA_As_requested_dd.mm.yyyy1: #N/A

Sheet Backlog+Comenzi de produs (2)
B9: Order Type | C9: (All)
B10: Order Finished YES/NO | C10: No
B11: Quarters (ETA As requested dd.mm.yyyy) | C11: (All)
E13: Years | F13: Months | G13: ETA | H13: Values
E14: 2024 | G14: 2025 | S14: 2025 Quantity | T14: 2025 Price/Order | U14: 2026 | AS14: 2026 Quantity | AT14: 2026 Price/Order | AU14: Total Quantity | AV14: Total Price/Order
G15: Mar | I15: Jul | K15: Sep | M15: Oct | O15: Nov | Q15: Dec | U15: Jan | W15: Feb | Y15: Mar | AA15: Apr | AC15: May | AE15: Jun | AG15: Jul | AI15: Aug | AK15: Sep | AM15: Oct | AO15: Nov | AQ15: Dec
B17: CUSTOMER | C17: Product Family | D17: Part Number | E17: Quantity | F17: Price/Order | G17: Quantity | H17: Price/Order | I17: Quantity | J17: Price/Order | K17: Quantity | L17: Price/Order | M17: Quantity | N17: Price/Order | O17: Quantity | P17: Price/Order | Q17: Quantity | R17: Price/Order | U17: Quantity | V17: Price/Order | W17: Quantity | X17: Price/Order | Y17: Quantity | Z17: Price/Order | AA17: Quantity | AB17: Price/Order | AC17: Quantity | AD17: Price/Order | AE17: Quantity | AF17: Price/Order | AG17: Quantity | AH17: Price/Order | AI17: Quantity | AJ17: Price/Order | AK17: Quantity | AL17: Price/Order | AM17: Quantity | AN17: Price/Order | AO17: Quantity | AP17: Price/Order | AQ17: Quantity | AR17: Price/Order
B18: BOSCH Blaj | E18: 2 | F18: 176.06 | M18: 683 | N18: 4180.54 | O18: 240 | P18: 4171.2 | Q18: 500 | R18: 7395.2 | S18: 1423 | T18: 15746.94 | U18: 340 | V18: 0 | W18: 580 | X18: 0 | Y18: 340 | Z18: 0 | AA18: 1080 | AB18: 0 | AC18: 340 | AD18: 0 | AE18: 240 | AF18: 0 | AG18: 340 | AH18: 0 | AI18: 240 | AJ18: 0 | AK18: 340 | AL18: 0 | AS18: 3840 | AT18: 0 | AU18: 5265 | AV18: 15923
B19: BOSCH Homburg | M19: 23 | N19: 122.13 | O19: 195 | P19: 2039.15 | Q19: 100 | R19: 97 | S19: 318 | T19: 2258.28 | U19: 396 | V19: 0 | W19: 120 | X19: 0 | Y19: 345 | Z19: 0 | AA19: 430 | AB19: 0 | AC19: 340 | AD19: 0 | AE19: 415 | AF19: 0 | AG19: 135 | AH19: 0 | AI19: 230 | AJ19: 0 | AK19: 630 | AL19: 0 | AM19: 130 | AN19: 0 | AO19: 69 | AP19: 0 | AQ19: 496 | AR19: 0 | AS19: 3736 | AT19: 0 | AU19: 4054 | AV19: 2258.28
B20: BOSCH Lohr | K20: 86 | L20: 499.66 | M20: 159 | N20: 9780.11 | O20: 1581 | P20: 16557.34 | Q20: 742 | R20: 13342.66 | S20: 2568 | T20: 40179.77 | U20: 2221 | V20: 2311.32 | W20: 872 | X20: 0 | Y20: 2209 | Z20: 0 | AA20: 1198 | AB20: 0 | AE20: 632 | AF20: 0 | AG20: 660 | AH20: 0 | AK20: 660 | AL20: 0 | AO20: 660 | AP20: 0 | AS20: 9112 | AT20: 2311.32 | AU20: 11680 | AV20: 42491.09
B21: Elbit | G21: 752 | H21: 79332.24 | K21: 15 | L21: 16506.15 | S21: 767 | T21: 95838.39 | AU21: 767 | AV21: 95838.39
B22: Orbit | K22: 14 | L22: 7696.65 | Q22: 9 | R22: 6465.6 | S22: 23 | T22: 14162.25 | AU22: 23 | AV22: 14162.25
B23: Schaeffler DE | E23: 102 | F23: 856.9 | Q23: 143 | R23: 2199.34 | S23: 143 | T23: 2199.34 | U23: 437 | V23: 8297.61 | Y23: 956 | Z23: 14360.98 | AA23: 30 | AB23: 0 | AS23: 1423 | AT23: 22658.59 | AU23: 1668 | AV23: 25714.83
B24: Schaeffler RO | I24: 5 | J24: 6.8 | M24: 794 | N24: 4384.76 | O24: 13372 | P24: 60319.77 | Q24: 14644 | R24: 47248.45 | S24: 28815 | T24: 111959.78 | AU24: 28815 | AV24: 111959.78
B25: Sadev | O25: 97 | P25: 97 | S25: 97 | T25: 97 | AU25: 97 | AV25: 97
B26: Grand Total | E26: 104 | F26: 1032.96 | G26: 752 | H26: 79332.24 | I26: 5 | J26: 6.8 | K26: 115 | L26: 24702.46 | M26: 1659 | N26: 18467.54 | O26: 15485 | P26: 83184.46 | Q26: 16138 | R26: 76748.25 | S26: 34154 | T26: 282441.75 | U26: 3394 | V26: 10608.93 | W26: 1572 | X26: 0 | Y26: 3850 | Z26: 14360.98 | AA26: 2738 | AB26: 0 | AC26: 680 | AD26: 0 | AE26: 1287 | AF26: 0 | AG26: 1135 | AH26: 0 | AI26: 470 | AJ26: 0 | AK26: 1630 | AL26: 0 | AM26: 130 | AN26: 0 | AO26: 729 | AP26: 0 | AQ26: 496 | AR26: 0 | AS26: 18111 | AT26: 24969.91 | AU26: 52369 | AV26: 308444.62

Sheet Orders
B9: Order Type | C9: (All)
B10: Order Finished YES/NO | C10: (All)
B11: Quarters (ETA As requested dd.mm.yyyy) | C11: (All)
B13: Sum of Quantity | E13: CUSTOMER | F13: CUSTOMER PO# | G13: Product Family | H13: Part Number
E14: Schaeffler DE | F14: Grand Total
B17: Years ) | C17: Months | D17: ETA
B18: 2024 | C18: May | E18: 225 | F18: 225
C19: Jun | E19: 308 | F19: 308
C20: Aug | E20: 63667 | F20: 63667
C21: Oct | E21: 363 | F21: 363
B22: 2024 Total | E22: 64563 | F22: 64563
B23: 2025 | C23: Jun | E23: 62 | F23: 62
C24: Dec | E24: 143 | F24: 143
B25: 2025 Total | E25: 205 | F25: 205
B26: Grand Total | E26: 64768 | F26: 64768

Sheet Livrari (2)
B6: Order Finished YES/NO | C6: (All)
B7: Order Type | C7: (All)
B8: Months (ETA As requested dd.mm.yyyy) | C8: (All)
B9: Years (ETA As requested dd.mm.yyyy) | C9: (All)
B10: Quarters (ETA As requested dd.mm.yyyy) | C10: (All)
B11: Date PO dd.mm.yyyy | C11: (All)
E13: Years | F13: Months | G13: Days | H13: Values
E14: 2025 | G14: 2025 Sum of OK | H14: 2025 Sum of Sales | I14: Total Sum of OK | J14: Total Sum of Sales
E15: Oct
B17: CUSTOMER | C17: Product Family | D17: Part Number | E17: Sum of OK | F17: Sum of Sales
B18: BOSCH Blaj | C18: Drosselboltzen | E18: 420 | F18: 7299.6 | G18: 420 | H18: 7299.6 | I18: 420 | J18: 7299.6
C19: Z2S 22 | E19: 300 | F19: 26409 | G19: 300 | H19: 26409 | I19: 300 | J19: 26409
B20: BOSCH Blaj Total | E20: 720 | F20: 33708.6 | G20: 720 | H20: 33708.6 | I20: 720 | J20: 33708.6
B21: BOSCH Homburg | E21: 10 | F21: 3000 | G21: 10 | H21: 3000 | I21: 10 | J21: 3000
B22: BOSCH Lohr | E22: 2856 | F22: 58859.57 | G22: 2856 | H22: 58859.57 | I22: 2856 | J22: 58859.57
B23: Elbit | C23: YAW PLATE | E23: 5 | F23: 2520.65 | G23: 5 | H23: 2520.65 | I23: 5 | J23: 2520.65
C24: CAMERA CLAMP | E24: 5 | F24: 2530.55 | G24: 5 | H24: 2530.55 | I24: 5 | J24: 2530.55
C25: BENCH ADAPTOR | E25: 5 | F25: 2511.9 | G25: 5 | H25: 2511.9 | I25: 5 | J25: 2511.9
B26: Elbit Total | E26: 15 | F26: 7563.1 | G26: 15 | H26: 7563.1 | I26: 15 | J26: 7563.1
B27: IGW | E27: 10 | F27: 5226 | G27: 10 | H27: 5226 | I27: 10 | J27: 5226
B28: Orbit | C28: AZIMUTH TURNTABLE, AL-4018-1RF | E28: 6 | F28: 4792.14 | G28: 6 | H28: 4792.14 | I28: 6 | J28: 4792.14
C29: EL. DRIVE (RIGHT) TURNTABLE, AL-4018-1RF | E29: 6 | F29: 3114.72 | G29: 6 | H29: 3114.72 | I29: 6 | J29: 3114.72
C30: PANEL ACCESS ELEVATION, AL-4018-1RF #30315 | E30: 6 | F30: 1458.66 | G30: 6 | H30: 1458.66 | I30: 6 | J30: 1458.66
B31: Orbit Total | E31: 18 | F31: 9365.52 | G31: 18 | H31: 9365.52 | I31: 18 | J31: 9365.52
B32: Schaeffler RO | E32: 23644 | F32: 51051.567 | G32: 23644 | H32: 51051.567 | I32: 23644 | J32: 51051.567
B33: Grand Total | E33: 27273 | F33: 168774.36 | G33: 27273 | H33: 168774.36 | I33: 27273 | J33: 168774.36

Sheet Livrari
B4: Order Finished YES/NO | C4: Yes
B5: Order Type | C5: (All)
B6: Months (ETA As requested dd.mm.yyyy) | C6: (All)
B7: Years (ETA As requested dd.mm.yyyy) | C7: (All)
B8: Quarters (ETA As requested dd.mm.yyyy) | C8: (All)
B9: Date PO dd.mm.yyyy | C9: (All)
B10: Product Family | C10: (All)
B11: AVIZ OLSTRAL | C11: (All)
B13: Sum of OK | G13: CUSTOMER
B14: Years | C14: Months | D14: Days | E14: CUSTOMER PO# | F14: Part Number | G14: Schaeffler RO | H14: Grand Total
B15: 2025 | C15: Sep | G15: 8222 | H15: 8222
C16: Oct | G16: 4185 | H16: 4185
B17: 2025 Total | G17: 12407 | H17: 12407
B18: Grand Total | G18: 12407 | H18: 12407

Sheet Sheet2
A1: Nr.comanda interna | B1: Data routing | C1: Ora | D1: Utilaj | E1: Reper | F1: Sarja | G1: Cantitate
A2: 240201 | E2: PBE 1400062752 | F2: 89466930 | G2: 10 bucati
A3: 240202 | E3: KUH 6036 | F3: 88821241 | G3: 42 calupi
A4: 240203 | E4: RKDK ZL | F4: 88962011 | G4: 924 bucati
A5: 240204 | E5: EDS F-607694-1038-ISB 000 AB | F5: 84159615 | G5: 298 bucati
A6: 240205 | E6: RKDK N222 | F6: 89151373 | G6: 22 calupi
A7: 240206 | E7: RB00690513 (1535100044) | F7: 3075576
A8: 240207 | E8: 1818509725 | F8: 279676
A9: 240208/1 | E9: EDS F-607694-1038-ISB 000 AB | F9: 84159615 | G9: 192 bucati
A10: 240209 | E10: KUH 6036 capete | F10: 88821241 | G10: 210 bucati = 42 calupi
A11: 240301 | E11: AUKB 2045B | G11: 6 bare
A12: 240302 | E12: KUH.6317 | F12: 89293208 | G12: 36 calupi
A13: 240303 | E13: R901469360/R900126765
A14: 240304 | E14: RKDK.N317-EA-M3-0042 | F14: 89288511 | G14: 48 calupi = 672 bucati
A15: 240305 | E15: B8C000021 | G15: 1 bara
A16: 240306 | E16: KWVE 30 BAS | F16: 86937618 | G16: 650 bucati
A17: 240307 | E17: KUH.6317 | F17: 89293208 | G17: capete
A18: 240308 | E18: EDS F-607694-1038-ISB 000 AB | F18: 2644388 | G18: 150 bucati
A19: 240309 | E19: 1818509284
A20: 240310 | E20: RB00690513 (1535100044) | F20: 3075576
A21: 240311 | E21: F 586360 | G21: 35 bucati
A22: 240312 | E22: AUKB 3068 | F22: 873065802 | G22: 5 + 5 bare (22.01)
A23: 240313 | E23: AUKB 2045B | G23: 15 bare
A24: 240314 | E24: KUH 6215 | F24: 89293273
A25: 240315 | E25: RKDK.N317-EA-M3-0042
A26: 240401 | E26: AUKB 2045B | G26: 15 bare
A27: 240402 | E27: R900145251 | G27: 105 bucati
A28: 240403 | E28: R900692452 | G28: 1 bucati
A29: 240404 | E29: R900305232 | F29: 2021050331 | G29: 40 bucati
A30: 240405 | E30: R901469360/R900126765 | F30: 2021050331 | G30: 3 bucati
A31: 240406 | E31: RKDK.N317-EA-M3-0042 | F31: 86971634 | G31: 8 + 32 bucati | H31: capete
A32: 240407 | E32: KWVE 30 BAS | F32: 8697618 | G32: 150 bucati
A33: 240408 | E33: EDS F-607694-1038-ISB 000 AB | F33: 2644388 | G33: 150 bucati
A34: 240409 | E34: KWVE 30 BAH | F34: 86937618 | G34: 250 bucati
A35: 240410 | E35: R900628302 | G35: 100 bucati
A36: 240411 | E36: AUKB 3068 | F36: 87306802 | G36: 15 bare = 450 piese
A37: 240412 | E37: 1813218042
A38: 240413 | E38: KWVE 30 BAS | F38: 86937618
A39: 240414 | E39: AUKB 2045B
A40: 240415 | E40: KWVE 30 BAS | F40: 86937618 | G40: 144 bucati
...

Sheet OTD
K1: 2024 | L1: Livrari-Delivery Data Analysis
L4: F_Q_300 REV.00-21/01/21
A6: KPI 5 | B6: KPI - Livrari - OTD = On Time Delivery TOTAL
A8: 2024 | B8: January | C8: February | D8: March | E8: April | F8: May | G8: June | H8: July | I8: August | J8: September | K8: October | L8: November | M8: December | N8: TOTAL | O8: Media
B9: Ianuarie | C9: Februarie | D9: Martie | E9: Aprilie | F9: Mai | G9: Iunie | H9: Iulie | I9: Agust | J9: Septembrie | K9: Octombrie | L9: Noiembrie | M9: Decembrie
A10: nr. de livrari | F10: =F24+F37+F50+F63 -> 304 | G10: =G24+G37+G50+G63 -> 284 | H10: =H24+H37+H50+H63 -> 312 | I10: =I24+I37+I50+I63 -> 248 | J10: =J24+J37+J50+J63 -> 0 | K10: =K24+K37+K50+K63 -> 0 | L10: =L24+L37+L50+L63 -> 0 | M10: =M24+M37+M50+M63 -> 0 | N10: =SUM(B10:M10) -> 1148 | O10: =AVERAGE(B10:M10) -> 143.5
A11: nr. de livrari la timp | F11: =F25+F38+F51+F64 -> 228 | G11: =G25+G38+G51+G64 -> 208 | H11: =H25+H38+H51+H64 -> 220 | I11: =I25+I38+I51+I64 -> 136 | J11: =J25+J38+J51+J64 -> 0 | K11: =K25+K38+K51+K64 -> 0 | L11: =L25+L38+L51+L64 -> 0 | M11: =M25+M38+M51+M64 -> 0 | N11: =SUM(B11:M11) -> 792 | O11: =AVERAGE(B11:M11) -> 99
A12: OTD Cda % | F12: =F11/F10 -> 0.75 | G12: =G11/G10 -> 0.73239437 | H12: =H11/H10 -> 0.70512821 | I12: =I11/I10 -> 0.5483871 | N12: =N11/N10 -> 0.68989547 | O12: =O11/O10 -> 0.68989547
A13: nr. de piese comandate | F13: =F27+F40+F53+F66 -> 1534 | G13: =G27+G40+G53+G66 -> 1068 | H13: =H27+H40+H53+H66 -> 3176 | I13: =I27+I40+I53+I66 -> 5708 | J13: =J27+J40+J53+J66 -> 0 | K13: =K27+K40+K53+K66 -> 0 | L13: =L27+L40+L53+L66 -> 0 | M13: =M27+M40+M53+M66 -> 0 | N13: =SUM(B13:M13) -> 11486 | O13: =AVERAGE(B13:M13) -> 1435.75
A14: Nr piese expediate | F14: =F28+F41+F54+F67 -> 684 | G14: =G28+G41+G54+G67 -> 386 | H14: =H28+H41+H54+H67 -> 2044 | I14: =I28+I41+I54+I67 -> 3594 | J14: =J28+J41+J54+J67 -> 0 | K14: =K28+K41+K54+K67 -> 0 | L14: =L28+L41+L54+L67 -> 0 | M14: =M28+M41+M54+M67 -> 0 | N14: =SUM(B14:M14) -> 6708 | O14: =AVERAGE(B14:M14) -> 838.5
A15: % de rebut | F15: =F14/F13 -> 0.44589309 | G15: =G14/G13 -> 0.36142322 | N15: =N14/N13 -> 0.58401532 | O15: =N15 -> 0.58401532
A16: OTD Qty % | B16: =B14/B13 -> #DIV/0! | C16: =C14/C13 -> #DIV/0! | D16: =D14/D13 -> #DIV/0! | E16: =E14/E13 -> #DIV/0! | F16: =F14/F13 -> 0.44589309 | G16: =G14/G13 -> 0.36142322 | H16: =H14/H13 -> 0.64357683 | I16: =I14/I13 -> 0.62964261 | N16: =(N14/N13) -> 0.58401532 | O16: =(O14/O13) -> 0.58401532
A17: Target >80% | B17: 0.8 | C17: 0.8 | D17: 0.8 | E17: 0.8 | F17: 0.8 | G17: 0.8 | H17: 0.8 | I17: 0.8 | J17: 0.8 | K17: 0.8 | L17: 0.8 | M17: 0.8
A20: KPI 5 | B20: KPI - Livrari - OTD= On Time Delivery BOSCH
A22: 2024 | B22: January | C22: February | D22: March | E22: April | F22: May | G22: June | H22: July | I22: August | J22: September | K22: October | L22: November | M22: December | N22: TOTAL | O22: Media
B23: Ianuarie | C23: Februarie | D23: Martie | E23: Aprilie | F23: Mai | G23: Iunie | H23: Iulie | I23: Agust | J23: Septembrie | K23: Octombrie | L23: Noiembrie | M23: Decembrie
A24: nr. de livrari | F24: 76 | G24: 71 | H24: 78 | I24: 62 | N24: =SUM(B24:M24) -> 287 | O24: =AVERAGE(B24:M24) -> 71.75
A25: nr. de livrari la timp | F25: 57 | G25: 52 | H25: 55 | I25: 34 | N25: =SUM(B25:M25) -> 198 | O25: =AVERAGE(B25:M25) -> 49.5
A26: OTD Cda % | F26: =F25/F24 -> 0.75 | G26: =G25/G24 -> 0.73239437 | H26: =H25/H24 -> 0.70512821 | I26: =I25/I24 -> 0.5483871 | N26: =N25/N24 -> 0.68989547 | O26: =O25/O24 -> 0.68989547
A27: nr. de piese comandate | F27: =F40+F53+F66 -> 767 | G27: =G40+G53+G66 -> 534 | H27: =H40+H53+H66 -> 1588 | I27: =I40+I53+I66 -> 2854 | N27: =SUM(B27:M27) -> 5743 | O27: =AVERAGE(B27:M27) -> 1435.75
A28: Nr piese expediate | F28: =F41+F54+F67 -> 342 | G28: =G41+G54+G67 -> 193 | H28: =H41+H54+H67 -> 1022 | I28: =I41+I54+I67 -> 1797 | N28: =SUM(B28:M28) -> 3354 | O28: =AVERAGE(B28:M28) -> 838.5
A29: OTD Qty % | B29: =B28/B27 -> #DIV/0! | C29: =C28/C27 -> #DIV/0! | D29: =D28/D27 -> #DIV/0! | E29: =E28/E27 -> #DIV/0! | F29: =F28/F27 -> 0.44589309 | G29: =G28/G27 -> 0.36142322 | H29: =H28/H27 -> 0.64357683 | I29: =I28/I27 -> 0.62964261 | N29: =(N28/N27) -> 0.58401532 | O29: =(O28/O27) -> 0.58401532
A30: Target >80% | B30: 0.8 | C30: 0.8 | D30: 0.8 | E30: 0.8 | F30: 0.8 | G30: 0.8 | H30: 0.8 | I30: 0.8 | J30: 0.8 | K30: 0.8 | L30: 0.8 | M30: 0.8
A33: KPI 5 | B33: KPI - Livrari - OTD= On Time Delivery BOSCH Lohr
A35: 2024 | B35: January | C35: February | D35: March | E35: April | F35: May | G35: June | H35: July | I35: August | J35: September | K35: October | L35: November | M35: December | N35: TOTAL | O35: Media
B36: Ianuarie | C36: Februarie | D36: Martie | E36: Aprilie | F36: Mai | G36: Iunie | H36: Iulie | I36: Agust | J36: Septembrie | K36: Octombrie | L36: Noiembrie | M36: Decembrie
A37: nr. de livrari | F37: 76 | G37: 71 | H37: 78 | I37: 62 | N37: =SUM(B37:M37) -> 287 | O37: =AVERAGE(B37:M37) -> 71.75
A38: nr. de livrari la timp | F38: 57 | G38: 52 | H38: 55 | I38: 34 | N38: =SUM(B38:M38) -> 198 | O38: =AVERAGE(B38:M38) -> 49.5
A39: OTD Cda % | F39: =F38/F37 -> 0.75 | G39: =G38/G37 -> 0.73239437 | H39: =H38/H37 -> 0.70512821 | I39: =I38/I37 -> 0.5483871 | N39: =N38/N37 -> 0.68989547 | O39: =O38/O37 -> 0.68989547
A40: nr. de piese comandate | F40: 164 | G40: 294 | H40: 271 | I40: 240 | N40: =SUM(B40:M40) -> 969 | O40: =AVERAGE(B40:M40) -> 242.25
A41: Nr piese expediate | F41: 102 | G41: 126 | H41: 144 | I41: 198 | N41: =SUM(B41:M41) -> 570 | O41: =AVERAGE(B41:M41) -> 142.5
A42: OTD Qty % | B42: =B41/B40 -> #DIV/0! | C42: =C41/C40 -> #DIV/0! | D42: =D41/D40 -> #DIV/0! | E42: =E41/E40 -> #DIV/0! | F42: =F41/F40 -> 0.62195122 | G42: =G41/G40 -> 0.42857143 | H42: =H41/H40 -> 0.53136531 | I42: =I41/I40 -> 0.825 | N42: =(N41/N40) -> 0.58823529 | O42: =(O41/O40) -> 0.58823529
A43: Target >80% | B43: 0.8 | C43: 0.8 | D43: 0.8 | E43: 0.8 | F43: 0.8 | G43: 0.8 | H43: 0.8 | I43: 0.8 | J43: 0.8 | K43: 0.8 | L43: 0.8 | M43: 0.8
A46: KPI 5 | B46: KPI - Livrari - OTD= On Time Delivery BOSCH Blaj
A48: 2024 | B48: January | C48: February | D48: March | E48: April | F48: May | G48: June | H48: July | I48: August | J48: September | K48: October | L48: November | M48: December | N48: TOTAL | O48: Media
B49: Ianuarie | C49: Februarie | D49: Martie | E49: Aprilie | F49: Mai | G49: Iunie | H49: Iulie | I49: Agust | J49: Septembrie | K49: Octombrie | L49: Noiembrie | M49: Decembrie
A50: nr. de livrari | F50: 76 | G50: 71 | H50: 78 | I50: 62 | N50: =SUM(B50:M50) -> 287 | O50: =AVERAGE(B50:M50) -> 71.75
A51: nr. de livrari la timp | F51: 57 | G51: 52 | H51: 55 | I51: 34 | N51: =SUM(B51:M51) -> 198 | O51: =AVERAGE(B51:M51) -> 49.5
A52: OTD Cda % | F52: =F51/F50 -> 0.75 | G52: =G51/G50 -> 0.73239437 | H52: =H51/H50 -> 0.70512821 | I52: =I51/I50 -> 0.5483871 | N52: =N51/N50 -> 0.68989547 | O52: =O51/O50 -> 0.68989547
A53: nr. de piese comandate | F53: 603 | G53: 240 | H53: 1317 | I53: 2598 | N53: =SUM(B53:M53) -> 4758 | O53: =AVERAGE(B53:M53) -> 1189.5
...

Sheet LOP_SupplyChain
B1: LOP SUPPLY CHAIN
B3: Data | C3: Client | D3: Prio | E3: Produs | F3: Problema | G3: Termen | H3: Cine | I3: Status
B4: 45534 | C4: Schaeffler RO | E4: EDS F-801632-1031.RKKM.ZL-M3A 000 | F4: Inchis cda cu clientul | G4: 45541
E5: F-801632-1042.D140.RKDK.ZL-M3AA | F5: material de client in w36! | G5: 45541
B6: 45538 | E6: Danfoss_NEW | F6: Proiect nou > cda, PPAP, etc | G6: 45541 | H6: Popa
B7: 45540 | E7: B85300050 | F7: material de achizitionat!
B8: 45540 | E8: F-801632-1042.D140.RKDK.ZL-M3AA | F8: inchidere cda | H8: Madalina
B9: 45541 | E9: F-320745-1701.HUE.ACT | F9: MP de achizitionat | H9: Madalina | I9: comandat
B10: 45541 | E10: F-320745-9001.VSHR.ACT | F10: MP de achizitionat | H10: Madalina | I10: comandat
B11: 45547 | E11: R900172405 | F11: MP de achizitionat
B13: 45551 | C13: Schaeffler RO | F13: Livrari Sept Ghidaje din stoc | G13: 45554 | H13: Madalina
B14: 45551 | C14: Bosch Lohr | E14: Plate | F14: Inventar + cda materiale | G14: 45551 | H14: Popa/Madalina
B15: 45551 | F15: HEC204 > capacitate disponibila w39 Ce se transfera? Housing Schaeffler de pe Matsura? DBD-uri? | H15: Popa
B16: 45551 | F16: Operatori Rectificare | H16: Popa
B17: 45551
B18: 45551
B19: 45551

Sheet Registru unic-FURNIZORI
K1: REGISTRU UNIC FURNIZORI | N1: din aceste date obtinem KPI 7
A7: NR CRT | B7: CUSTOMER | C7: PART NUMBER | D7: RAW MATERIAL | E7: DIMENSIONS (mm) | F7: FAMILY | G7: SUPPLIER | H7: OBS
A8: 1 | B8: Edwards | C8: B85300050 | D8: AlSiMgMn T6 | E8: Ø140x15x160 | F8: Teava | G8: Tehnodistcom | H8: 3 piese
A9: 2 | B9: Walterscheid | C9: 557809 | D9: 16/20MnCr5 laminat | E9: Ø105 (+6) x 100 | F9: Bara | G9: Tehnodistcom | H9: Dimensiune dupa debitare
A10: 3 | B10: Bosch Lohr | C10: R900305241 | D10: EN-GJS-400-15C | E10: 130x90x1575 | F10: Bara | G10: ACO Guss Gmbh | H10: Debitare la 184 - Vectra
A11: 4 | B11: Bosch Lohr | C11: R900305244 | D11: EN-GJS-400-15C | E11: 130x90x1575 | F11: Bara | G11: ACO Guss Gmbh | H11: Debitare la 184 - Vectra
A12: 5 | B12: Bosch Lohr | C12: R900305248 | D12: EN-GJS-400-15C | E12: 130x90x1575 | F12: Bara | G12: ACO Guss Gmbh | H12: Debitare la 184 - Vectra
A13: 6 | B13: Bosch Lohr | C13: R901157146 | D13: EN-GJS-400-15C | E13: 130x90x1575 | F13: Bara | G13: ACO Guss Gmbh | H13: Debitare la 184 - Vectra
A14: 7 | B14: Bosch Lohr | C14: R901469368 | D14: EN-GJS-400-15C | E14: 130x90x1575 | F14: Bara | G14: ACO Guss Gmbh | H14: Debitare la 184 - Vectra
A15: 8 | B15: Bosch Lohr | C15: R901157145 | D15: EN-GJS-400-15C | E15: 130x90x1575 | F15: Bara | G15: ACO Guss Gmbh | H15: Debitare la 184 - Vectra
A16: 9 | B16: Bosch Lohr | C16: R901469366 | D16: EN-GJS-400-15C | E16: 130x90x1575 | F16: Bara | G16: ACO Guss Gmbh | H16: Debitare la 184 - Vectra
A17: 10 | B17: Bosch Homburg | C17: 1813218050 | D17: 100Cr6 | E17: Ø16x3000 | F17: Bara | G17: Tehnodistcom
A18: 11 | B18: Liebherr | C18: 39267-13 | D18: Aluminiu (T351 25.4X) | E18: 130x80x25.4 | F18: Tabla | G18: Gilinox
A19: 12 | B19: Liebherr | C19: 39267-13 | D19: Al 2024 | E19: 130x80x25 | F19: Placa debitata | G19: Tehnodistcom
A20: 13 | B20: Bosch Lohr | C20: R900305231 | D20: 11SMn30+C | E20: 80x60x2900 | F20: Bara | G20: Heine + Beisswenger | H20: Debitare la 104 - Vectra
A21: 14 | B21: Bosch Lohr | C21: R900305247 | D21: EN-GJS-400-15C | E21: 130x90x1575 | F21: Bara | G21: Heine + Beisswenger | H21: Debitare la 184 - Vectra
A22: 15 | B22: Bosch Lohr | C22: R901190149 | D22: 11SMn30+C | E22: 80x60x2900 | F22: Bara | G22: Heine + Beisswenger | H22: Debitare la 104 - Vectra
A23: 16 | B23: Bosch Lohr | C23: R901190153 | D23: 11SMn30+C | E23: 80x60x2900 | F23: Bara | G23: Heine + Beisswenger | H23: Debitare la 104 - Vectra
A24: 17 | B24: Bosch Lohr | C24: R900305228 | D24: 11SMn30+C | E24: 80x60x2900 | F24: Bara | G24: Heine + Beisswenger | H24: Debitare la 104 - Vectra
A25: 18 | B25: Bosch Lohr | C25: R900305232 | D25: 11SMn30+C | E25: 80x60x2900 | F25: Bara | G25: Heine + Beisswenger | H25: Debitare la 104 - Vectra
A26: 19 | B26: Bosch Lohr | C26: R901469358 | D26: 11SMn30+C | E26: 80x60x2900 | F26: Bara | G26: Heine + Beisswenger | H26: Debitare la 104 - Vectra
A27: 20 | B27: Bosch Lohr | C27: R900305223 | D27: 11SMn30+C | E27: 80x60x2900 | F27: Bara | G27: Heine + Beisswenger | H27: Debitare la 104 - Vectra
A28: 21 | B28: Bosch Lohr | C28: R900305233 | D28: 11SMn30+C | E28: 100x70x2900 | F28: Bara | G28: Heine + Beisswenger | H28: Debitare la 139 - Vectra
A29: 22 | B29: Bosch Lohr | C29: R900305236 | D29: 11SMn30+C | E29: 100x70x2900 | F29: Bara | G29: Heine + Beisswenger | H29: Debitare la 139 - Vectra
A30: 23 | B30: Bosch Lohr | C30: R900305239 | D30: 11SMn30+C | E30: 100x70x2900 | F30: Bara | G30: Heine + Beisswenger | H30: Debitare la 139 - Vectra
A31: 24 | B31: Bosch Lohr | C31: R900305240 | D31: 11SMn30+C | E31: 100x70x2900 | F31: Bara | G31: Heine + Beisswenger | H31: Debitare la 139 - Vectra
... A35: 28 | B35: Bosch Lohr | C35: R901469362 | D35: 11SMn30+C | E35: 100x70x2900 | F35: Bara | G35: Heine + Beisswenger | H35: Debitare la 139 - Vectra
A36: 29 | B36: Liebherr | C36: S4673-08BA | D36: Inox W1.4
A37: 30
A38: 31
A39: 32
A40: 33
A41: 34
A42: 35
A43: 36
A44: 37
A45: 38
A46: 39
A47: 40
A48: 41
...

Sheet list
A1: Customer | E1: Subcontractare | G1: tip
A2: Schaeffler RO | E2: yes | G2: approved
A3: Schaeffler DE | E3: no | G3: project
A4: BOSCH Homburg
A5: BOSCH Lohr
A6: BOSCH Blaj
A7: IGW
A8: PAS Technologies
A9: Edwards
A10: Walterscheid
A11: Zeiss
A12: Alfons Haar
A13: Elbit
A14: Orbit
A15: Sadev

Sheet Database_Routing
A1: EDP KUH.6214-A-M-3001 004
A2: Item Name | B2: Links | C2: Client | D2: OK/NOK | E2: Spalte1
A4: EDP KU7208-B-MP-0031 000 | B4: \\192.168.0.252\4.productie\CLIENTI\SCHAEFFLER\01_Alama\EDP KU7208-B-MP-0031 000 | C4: SCHAEFFLER
A5: EDP KU7220-B-MP-0031 000 | B5: \\192.168.0.252\4.productie\CLIENTI\SCHAEFFLER\01_Alama\EDP KU7220-B-MP-0031 000 | C5: SCHAEFFLER
A6: EDP KUH.6030-M-3001 004 | B6: \\192.168.0.252\4.productie\CLIENTI\SCHAEFFLER\01_Alama\EDP KUH.6030-M-3001 004 | C6: SCHAEFFLER
A7: EDP KUH.6036-A-M-3001B | B7: \\192.168.0.252\4.productie\CLIENTI\SCHAEFFLER\01_Alama\EDP KUH.6036-A-M-3001B | C7: SCHAEFFLER
A8: EDP KUH.6214-A-M-3001 004 | B8: \\192.168.0.252\4.productie\CLIENTI\SCHAEFFLER\01_Alama\EDP KUH.6214-A-M-3001 004 | C8: SCHAEFFLER
A9: EDP KUH.6215-A-M-3001 004 | B9: \\192.168.0.252\4.productie\CLIENTI\SCHAEFFLER\01_Alama\EDP KUH.6215-A-M-3001 004 | C9: SCHAEFFLER
A10: EDP KUH.6217-B-M-3001 004 | B10: \\192.168.0.252\4.productie\CLIENTI\SCHAEFFLER\01_Alama\EDP KUH.6217-B-M-3001 004 | C10: SCHAEFFLER
A11: EDP KUH.6220-A-M-3001 004 | B11: \\192.168.0.252\4.productie\CLIENTI\SCHAEFFLER\01_Alama\EDP KUH.6220-A-M-3001 004 | C11: SCHAEFFLER | D11: OK
A13: EDP KUH.6222-A-M-3001B | B13: \\192.168.0.252\4.productie\CLIENTI\SCHAEFFLER\01_Alama\EDP KUH.6222-A-M-3001B | C13: SCHAEFFLER
A14: EDP KUH.6312-M-3001 004 | B14: \\192.168.0.252\4.productie\CLIENTI\SCHAEFFLER\01_Alama\EDP KUH.6312-M-3001 004 | C14: SCHAEFFLER | F14: B853000050
A15: EDP KUH.6315-A-M-3001 004 | B15: \\192.168.0.252\4.productie\CLIENTI\SCHAEFFLER\01_Alama\EDP KUH.6315-A-M-3001 004 | C15: SCHAEFFLER | D15: OK | F15: CZR0015562
A16: EDP KUH.6316-A-M-3001 004 | B16: \\192.168.0.252\4.productie\CLIENTI\SCHAEFFLER\01_Alama\EDP KUH.6316-A-M-3001 004 | C16: SCHAEFFLER | F16: XR100548
A17: EDP KUH.6317-A-M-3001 004 | B17: \\192.168.0.252\4.productie\CLIENTI\SCHAEFFLER\01_Alama\EDP KUH.6317-A-M-3001 004 | C17: SCHAEFFLER | D17: OK | F17: XR100546
A18: EDP KUH.6326-M-3001 004 | B18: \\192.168.0.252\4.productie\CLIENTI\SCHAEFFLER\01_Alama\EDP KUH.6326-M-3001 004 | C18: SCHAEFFLER
A19: EDP KUK.QJ205-C-MPA-3001 004 | B19: \\192.168.0.252\4.productie\CLIENTI\SCHAEFFLER\01_Alama\EDP KUK.QJ205-C-MPA-3001 004 | C19: SCHAEFFLER
A20: EDP KUK.QJ206-C-MPA-3001 004 | B20: \\192.168.0.252\4.productie\CLIENTI\SCHAEFFLER\01_Alama\EDP KUK.QJ206-C-MPA-3001 004 | C20: SCHAEFFLER
A21: EDP KUK.QJ207-C-MPA-3001 004 | B21: \\192.168.0.252\4.productie\CLIENTI\SCHAEFFLER\01_Alama\EDP KUK.QJ207-C-MPA-3001 004 | C21: SCHAEFFLER
A22: EDP KUK.QJ212-C-MPA-0031 000 | B22: \\192.168.0.252\4.productie\CLIENTI\SCHAEFFLER\01_Alama\EDP KUK.QJ212-C-MPA-0031 000 | C22: SCHAEFFLER
A23: EDP KUK.QJ213-CA-MPA-3001 | B23: \\192.168.0.252\4.productie\CLIENTI\SCHAEFFLER\01_Alama\EDP KUK.QJ213-CA-MPA-3001 | C23: SCHAEFFLER
A24: EDP KUK.QJ218-C-MPA-3001 | B24: \\192.168.0.252\4.productie\CLIENTI\SCHAEFFLER\01_Alama\EDP KUK.QJ218-C-MPA-3001 | C24: SCHAEFFLER
A25: EDP KUQJ213-CA-MPA-0031 000 | B25: \\192.168.0.252\4.productie\CLIENTI\SCHAEFFLER\01_Alama\EDP KUQJ213-CA-MPA-0031 000 | C25: SCHAEFFLER
A26: EDP KUQJ308-C-MPA-0031-000 | B26: \\192.168.0.252\4.productie\CLIENTI\SCHAEFFLER\01_Alama\EDP KUQJ308-C-MPA-0031-000 | C26: SCHAEFFLER
A27: EDP RKKM.N2220-EB-M3-0031 000 | B27: \\192.168.0.252\4.productie\CLIENTI\SCHAEFFLER\01_Alama\EDP RKKM.N2220-EB-M3-0031 000 | C27: SCHAEFFLER
A28: EDP RKKM.N416-M3-1031 000 | B28: \\192.168.0.252\4.productie\CLIENTI\SCHAEFFLER\01_Alama\EDP RKKM.N416-M3-1031 000 | C28: SCHAEFFLER
A29: EDS F-801631-1032.RKKM.ZL-M3A | B29: \\192.168.0.252\4.productie\CLIENTI\SCHAEFFLER\01_Alama\EDS F-801631-1032.RKKM.ZL-M3A | C29: SCHAEFFLER | D29: OK
A30: EDS KUH.6030-M-3001 | B30: \\192.168.0.252\4.productie\CLIENTI\SCHAEFFLER\01_Alama\EDS KUH.6030-M-3001 | C30: SCHAEFFLER
A31: EDS KUK.QJ205-C-MPA-3002 004 | B31: \\192.168.0.252\4.productie\CLIENTI\SCHAEFFLER\01_Alama\EDS KUK.QJ205-C-MPA-3002 004 | C31: SCHAEFFLER
A32: EDS KUK.QJ215-C-MPA-3001B | B32: \\192.168.0.252\4.productie\CLIENTI\SCHAEFFLER\01_Alama\EDS KUK.QJ215-C-MPA-3001B | C32: SCHAEFFLER
A33: EDS KUK.QJ215-C-MPA-3002 004 | B33: \\192.168.0.252\4.productie\CLIENTI\SCHAEFFLER\01_Alama\EDS KUK.QJ215-C-MPA-3002 004 | C33: SCHAEFFLER
A34: EDS_F-801632-1032_RKKM_ZL-M3A_000_AC | B34: \\192.168.0.252\4.productie\CLIENTI\SCHAEFFLER\01_Alama\EDS_F-801632-1032_RKKM_ZL-M3A_000_AC | C34: SCHAEFFLER | D34: OK
A35: EDS_RKDK_N217-E-Y3-1042_000_AA | B35: \\192.168.0.252\4.productie\CLIENTI\SCHAEFFLER\01_Alama\EDS_RKDK_N217-E-Y3-1042_000_AA | C35: SCHAEFFLER | D35: OK
A36: F-801632-0042.D140.RKDK.ZL-M3AA | B36: \\192.168.0.252\4.productie\CLIENTI\SCHAEFFLER\01_Alama\F-801632-0042.D140.RKDK.ZL-M3AA | C36: SCHAEFFLER | D36: OK
A37: RKDK.N222-EA-M3-0042 | B37: \\192.168.0.252\4.productie\CLIENTI\SCHAEFFLER\01_Alama\RKDK.N222-EA-M3-0042 | C37: SCHAEFFLER | D37: OK
A38: RKDK.N316-EA-M3-0042 | B38: \\192.168.0.252\4.productie\CLIENTI\SCHAEFFLER\01_Alama\RKDK.N316-EA-M3-0042 | C38: SCHAEFFLER | D38: OK
A39: RKDK.N317-EA-M3-0042 | B39: \\192.168.0.252\4.productie\CLIENTI\SCHAEFFLER\01_Alama\RKDK.N317-EA-M3-0042 | C39: SCHAEFFLER | D39: OK
A40: EDP_KUH_6015-A-M-3001_004_AD | B40: \\192.168.0.252\4.productie\CLIENTI\SCHAEFFLER\01_Alama\COLIVII ALAMA\EDP_KUH_6015-A-M-3001_004_AD | C40: SCHAEFFLER
A41: EDP_RKKM_N1012-M3-1031_000_AC | B41: \\192.168.0.252\4.productie\CLIENTI\SCHAEFFLER\01_Alama\COLIVII ALAMA\EDP_RKKM_N1012-M3-1031_000_AC | C41: SCHAEFFLER
A42: EDP_RKKM_N1014-M3-1031_000_AE | B42: \\192.168.0.252\4.productie\CLIENTI\SCHAEFFLER\01_Alama\COLIVII ALAMA\EDP_RKKM_N1014-M3-1031_000_AE | C42: SCHAEFFLER
...

Sheet Backlog+Comenzi de produs
B9: Order Type | C9: (All)
B10: Order Finished YES/NO | C10: No
B11: Quarters (ETA As requested dd.mm.yyyy) | C11: (All)
B13: Sum of Quantity | F13: Years | G13: Months | H13: ETA
F14: 2025 | G14: 2025 Total | H14: 2026 | K14: 2026 Total | L14: Grand Total
F15: Dec | H15: Jan | I15: Mar | J15: Apr
B16: CUSTOMER | C16: Product Family | D16: CUSTOMER PO# | E16: Part Number
B17: Schaeffler DE | C17: 0 | D17: 50589962 | E17: EDP PL.LFDL52-B-0021 000 | J17: 30 | K17: 30 | L17: 30
C18: 0 Total | J18: 30 | K18: 30 | L18: 30
C19: Adapterplatte | D19: 6049234 | E19: F-320745-0321.APL.ACT | I19: 260 | K19: 260 | L19: 260
D20: 50483888 | E20: F-320745-0321.APL.ACT | H20: 148 | K20: 148 | L20: 148
C21: Adapterplatte Total | H21: 148 | I21: 260 | K21: 408 | L21: 408
C22: Cover | D22: 6049233 | E22: F-320745-1901.DL.ACT15 | I22: 148 | K22: 148 | L22: 148
D23: 50483896 | E23: F-320745-1901.DL.ACT15 | H23: 146 | K23: 146 | L23: 146
C24: Cover Total | H24: 146 | I24: 148 | K24: 294 | L24: 294
C25: Druckstuck | D25: 6049236 | E25: F-320745-1401.BZ.ACT | I25: 143 | K25: 143 | L25: 143
D26: 50483858 | E26: F-320745-1401.BZ.ACT | F26: 143 | G26: 143 | L26: 143
C27: Druckstuck Total | F27: 143 | G27: 143 | I27: 143 | K27: 143 | L27: 286
C28: Sealing screw | D28: 6049232 | E28: F-320745-9001.VSHR.ACT | I28: 145 | K28: 145 | L28: 145
C29: Sealing screw Total | I29: 145 | K29: 145 | L29: 145
C30: sleeve | D30: 6049235 | E30: F-320745-1701.HUE.ACT | I30: 260 | K30: 260 | L30: 260
D31: 50483907 | E31: F-320745-1701.HUE.ACT | H31: 143 | K31: 143 | L31: 143
C32: sleeve Total | H32: 143 | I32: 260 | K32: 403 | L32: 403
B33: Schaeffler DE Total | F33: 143 | G33: 143 | H33: 437 | I33: 956 | J33: 30 | K33: 1423 | L33: 1566
B34: Grand Total | F34: 143 | G34: 143 | H34: 437 | I34: 956 | J34: 30 | K34: 1423 | L34: 1566

Sheet Registru unic-CLIENTI
Z1: REGISTRU UNIC DE LIVRARI la CLIENTI | AC1: din aceste date obtinem KPI 5
AL2: =TODAY() -> 45967
A8: SO DATA | J8: SC INPUT | K8: DATABASE FINISHED GOODS | S8: SC INPUT | AB8: DELIVERY INPUT | AJ8: ACCOUNTING
A9: CUSTOMER | B9: Order Type | C9: CUSTOMER PO# | D9: Date PO dd.mm.yyyy | E9: Part Number | F9: Part Description | G9: Drawing Revision | H9: Price/Unit EUR | I9: Quantity | J9: Price/Order | K9: ETA As requested dd.mm.yyyy | L9: ETA Confirmed dd.mm.yyyy | M9: ETA Planned dd.mm.yyyy | N9: Leadtime Contract days | O9: Product Family | P9: MOQ pcs | Q9: Frozen Zone days | R9: Status PPAP (approved/project) | S9: Mfg Lead Time days | T9: Subcontract | U9: Stock Warehouse pcs | V9: Scrap Rate | W9: Raw Material Status | X9: Incomming Date | Y9: Planned YES/NO | Z9: Work Order | AA9: Order Finished YES/NO | AB9: Dată de livrare | AC9: AVIZ OLSTRAL | AD9: COMANDĂ | AE9: REPER | AF9: OK | AG9: Sales | AH9: NOK | AI9: Observații | AJ9: Factură/Serie | AK9: OTD | AL9: Month | AM9: YEAR | AN9: Column1
A10: Schaeffler RO | B10: firm | C10: 7000971923 | D10: 45833 | E10: 154805.12 | F10: =IFERROR(VLOOKUP(Table1[[#This Row],[Part Number]],DATABASE_FG!$C$6:D9999,2,FALSE)," ") -> bucsa | G10: =IFERROR(_xlfn.XLOOKUP(Table1[[#This Row],[Part Number]],Table3[Part number],Table3[Drawing Revision]),"") -> 0 | H10: {=IFERROR(INDEX(PDB!$C:$AT,MATCH(E10,PDB!$B:$B,0),MATCH(YEAR(K10),0+PDB!$C$1:$AT$1,0)),"")} -> 5.32 | I10: 5 | J10: =IFERROR(Table1[[#This Row],[Quantity]]*Table1[[#This Row],[Price/Unit EUR]]," ") -> 26.6 | K10: 45838 | L10: =WEEKNUM(Table1[[#This Row],[ETA As requested dd.mm.yyyy]]) -> 27 | M10: =YEAR(Table1[[#This Row],[ETA As requested dd.mm.yyyy]]) -> 2025 | N10: =IFERROR(INDEX(DATABASE_FG!$H$5:$H$367, MATCH(E10, DATABASE_FG!$C$5:$C$367, 0)), " ") -> 0 | O10: =IF(E10<>"", _xlfn.XLOOKUP(E10, DATABASE_FG!C:C, DATABASE_FG!F:F), " ") -> Strunjire moale | P10: =IFERROR(INDEX(DATABASE_FG!$G$5:$G$367, MATCH(E10, DATABASE_FG!$C$5:$C$367, 0)), "Not Found") -> 0 | R10: approved | S10: =IFERROR(INDEX(DATABASE_FG!$L$5:$L$367, MATCH(E10, DATABASE_FG!$C$5:$C$367, 0)), " ") -> 0 | T10: no | AA10: Yes | AB10: 45835 | AC10: 26000 | AD10: =IF(NOT(ISBLANK(AC10)), C10, "") -> 7000971923 | AE10: =IF(NOT(ISBLANK(AC10)), E10, "") -> 154805.12 | AF10: 5 | AG10: =AF10*H10 -> 26.6 | AJ10: 20250802-27.06.2025 | AK10: =IF(AB10="", IF(K10 < TODAY(), "Late", ""), IF(AB10 <= K10 + 2, "On Time", "Late")) -> On Time | AL10: =TEXT(K10,"mmmm") -> June | AM10: =YEAR(Table1[[#This Row],[ETA As requested dd.mm.yyyy]]) -> 2025
A11: Schaeffler RO | B11: firm | C11: 7000971923 | D11: 45833 | E11: 154805.12 | F11: =IFERROR(VLOOKUP(Table1[[#This Row],[Part Number]],DATABASE_FG!$C$6:D10000,2,FALSE)," ") -> bucsa | G11: =IFERROR(_xlfn.XLOOKUP(Table1[[#This Row],[Part Number]],Table3[Part number],Table3[Drawing Revision]),"") -> 0 | H11: {=IFERROR(INDEX(PDB!$C:$AT,MATCH(E11,PDB!$B:$B,0),MATCH(YEAR(K11),0+PDB!$C$1:$AT$1,0)),"")} -> 5.32 | I11: 500 | J11: =IFERROR(Table1[[#This Row],[Quantity]]*Table1[[#This Row],[Price/Unit EUR]]," ") -> 2660 | K11: 45838 | L11: =WEEKNUM(Table1[[#This Row],[ETA As requested dd.mm.yyyy]]) -> 27 | M11: =YEAR(Table1[[#This Row],[ETA As requested dd.mm.yyyy]]) -> 2025 | N11: =IFERROR(INDEX(DATABASE_FG!$H$5:$H$367, MATCH(E11, DATABASE_FG!$C$5:$C$367, 0)), " ") -> 0 | O11: =IF(E11<>"", _xlfn.XLOOKUP(E11, DATABASE_FG!C:C, DATABASE_FG!F:F), " ") -> Strunjire moale | P11: =IFERROR(INDEX(DATABASE_FG!$G$5:$G$367, MATCH(E11, DATABASE_FG!$C$5:$C$367, 0)), "Not Found") -> 0 | R11: approved | S11: =IFERROR(INDEX(DATABASE_FG!$L$5:$L$367, MATCH(E11, DATABASE_FG!$C$5:$C$367, 0)), " ") -> 0 | T11: no | AA11: Yes | AB11: 45835 | AC11: 260002 | AD11: =IF(NOT(ISBLANK(AC11)), C11, "") -> 7000971923 | AE11: =IF(NOT(ISBLANK(AC11)), E11, "") -> 154805.12 | AF11: 500 | AG11: =AF11*H11 -> 2660 | AJ11: 20250803-27.06.2025 | AK11: =IF(AB11="", IF(K11 < TODAY(), "Late", ""), IF(AB11 <= K11 + 2, "On Time", "Late")) -> On Time | AL11: =TEXT(K11,"mmmm") -> June | AM11: =YEAR(Table1[[#This Row],[ETA As requested dd.mm.yyyy]]) -> 2025
A12: Walterscheid | B12: firm | C12: 5500000781 | D12: 45320 | E12: 557809 | F12: =IFERROR(VLOOKUP(Table1[[#This Row],[Part Number]],DATABASE_FG!$C$6:D10001,2,FALSE)," ") -> ANLAUFSCHEIBE | G12: =IFERROR(_xlfn.XLOOKUP(Table1[[#This Row],[Part Number]],Table3[Part number],Table3[Drawing Revision]),"") -> e | H12: {=IFERROR(INDEX(PDB!$C:$AT,MATCH(E12,PDB!$B:$B,0),MATCH(YEAR(K12),0+PDB!$C$1:$AT$1,0)),"")} -> 10.79 | I12: 100 | J12: =IFERROR(Table1[[#This Row],[Quantity]]*Table1[[#This Row],[Price/Unit EUR]]," ") -> 1079 | K12: 45392 | L12: =WEEKNUM(Table1[[#This Row],[ETA As requested dd.mm.yyyy]]) -> 15 | M12: =YEAR(Table1[[#This Row],[ETA As requested dd.mm.yyyy]]) -> 2024 | N12: =IFERROR(INDEX(DATABASE_FG!$H$5:$H$367, MATCH(E12, DATABASE_FG!$C$5:$C$367, 0)), " ") -> 0 | O12: =IF(E12<>"", _xlfn.XLOOKUP(E12, DATABASE_FG!C:C, DATABASE_FG!F:F), " ") -> 0 | P12: =IFERROR(INDEX(DATABASE_FG!$G$5:$G$367, MATCH(E12, DATABASE_FG!$C$5:$C$367, 0)), "Not Found") -> 200 | R12: approved | S12: =IFERROR(INDEX(DATABASE_FG!$L$5:$L$367, MATCH(E12, DATABASE_FG!$C$5:$C$367, 0)), " ") -> 56 | T12: yes | Z12: 240609 | AA12: Yes | AB12: 45404 | AC12: 2024387 | AD12: =IF(NOT(ISBLANK(AC12)), C12, "") -> 5500000781 | AE12: =IF(NOT(ISBLANK(AC12)), E12, "") -> 557809 | AF12: 100 | AG12: =AF12*H12 -> 1079 | AJ12: 20240425-22.04.2025 | AK12: =IF(AB12="", IF(K12 < TODAY(), "Late", ""), IF(AB12 <= K12 + 2, "On Time", "Late")) -> Late | AL12: =TEXT(K12,"mmmm") -> April | AM12: =YEAR(Table1[[#This Row],[ETA As requested dd.mm.yyyy]]) -> 2024
A13: Walterscheid | B13: firm | C13: 5500000781 | D13: 45320 | E13: 557809 | F13: =IFERROR(VLOOKUP(Table1[[#This Row],[Part Number]],DATABASE_FG!$C$6:D10002,2,FALSE)," ") -> ANLAUFSCHEIBE | G13: =IFERROR(_xlfn.XLOOKUP(Table1[[#This Row],[Part Number]],Table3[Part number],Table3[Drawing Revision]),"") -> e | H13: {=IFERROR(INDEX(PDB!$C:$AT,MATCH(E13,PDB!$B:$B,0),MATCH(YEAR(K13),0+PDB!$C$1:$AT$1,0)),"")} -> 10.79 | I13: 100 | J13: =IFERROR(Table1[[#This Row],[Quantity]]*Table1[[#This Row],[Price/Unit EUR]]," ") -> 1079 | K13: 45406 | L13: =WEEKNUM(Table1[[#This Row],[ETA As requested dd.mm.yyyy]]) -> 17 | M13: =YEAR(Table1[[#This Row],[ETA As requested dd.mm.yyyy]]) -> 2024 | N13: =IFERROR(INDEX(DATABASE_FG!$H$5:$H$367, MATCH(E13, DATABASE_FG!$C$5:$C$367, 0)), " ") -> 0 | O13: =IF(E13<>"", _xlfn.XLOOKUP(E13, DATABASE_FG!C:C, DATABASE_FG!F:F), " ") -> 0 | P13: =IFERROR(INDEX(DATABASE_FG!$G$5:$G$367, MATCH(E13, DATABASE_FG!$C$5:$C$367, 0)), "Not Found") -> 200 | R13: approved | S13: =IFERROR(INDEX(DATABASE_FG!$L$5:$L$367, MATCH(E13, DATABASE_FG!$C$5:$C$367, 0)), " ") -> 56 | T13: yes | Z13: 240609 | AA13: Yes | AB13: 45404 | AC13: 2024387 | AD13: =IF(NOT(ISBLANK(AC13)), C13, "") -> 5500000781 | AE13: =IF(NOT(ISBLANK(AC13)), E13, "") -> 557809 | AF13: 100 | AG13: =AF13*H13 -> 1079 | AJ13: 20240425-22.04.2025 | AK13: =IF(AB13="", IF(K13 < TODAY(), "Late", ""), IF(AB13 <= K13 + 2, "On Time", "Late")) -> On Time | AL13: =TEXT(K13,"mmmm") -> April | AM13: =YEAR(Table1[[#This Row],[ETA As requested dd.mm.yyyy]]) -> 2024
A14: Walterscheid | B14: firm | C14: 5500000781 | D14: 45320 | E14: 557809 | F14: =IFERROR(VLOOKUP(Table1[[#This Row],[Part Number]],DATABASE_FG!$C$6:D10003,2,FALSE)," ") -> ANLAUFSCHEIBE | G14: =IFERROR(_xlfn.XLOOKUP(Table1[[#This Row],[Part Number]],Table3[Part number],Table3[Drawing Revision]),"") -> e | H14: {=IFERROR(INDEX(PDB!$C:$AT,MATCH(E14,PDB!$B:$B,0),MATCH(YEAR(K14),0+PDB!$C$1:$AT$1,0)),"")} -> 10.79 | I14: 100 | J14: =IFERROR(Table1[[#This Row],[Quantity]]*Table1[[#This Row],[Price/Unit EUR]]," ") -> 1079 | K14: 45427 | L14: =WEEKNUM(Table1[[#This Row],[ETA As requested dd.mm.yyyy]]) -> 20 | M14: =YEAR(Table1[[#This Row],[ETA As requested dd.mm.yyyy]]) -> 2024 | N14: =IFERROR(INDEX(DATABASE_FG!$H$5:$H$367, MATCH(E14, DATABASE_FG!$C$5:$C$367, 0)), " ") -> 0 | O14: =IF(E14<>"", _xlfn.XLOOKUP(E14, DATABASE_FG!C:C, DATABASE_FG!F:F), " ") -> 0 | P14: =IFERROR(INDEX(DATABASE_FG!$G$5:$G$367, MATCH(E14, DATABASE_FG!$C$5:$C$367, 0)), "Not Found") -> 200 | R14: approved | S14: =IFERROR(INDEX(DATABASE_FG!$L$5:$L$367, MATCH(E14, DATABASE_FG!$C$5:$C$367, 0)), " ") -> 56 | T14: yes | Z14: 240609 | AA14: Yes | AB14: 45404 | AC14: 2024387 | AD14: =IF(NOT(ISBLANK(AC14)), C14, "") -> 5500000781 | AE14: =IF(NOT(ISBLANK(AC14)), E14, "") -> 557809 | AF14: 100 | AG14: =AF14*H14 -> 1079 | AJ14: 20240425-22.04.2025 | AK14: =IF(AB14="", IF(K14 < TODAY(), "Late", ""), IF(AB14 <= K14 + 2, "On Time", "Late")) -> On Time | AL14: =TEXT(K14,"mmmm") -> May | AM14: =YEAR(Table1[[#This Row],[ETA As requested dd.mm.yyyy]]) -> 2024
A15: Walterscheid | B15: firm | C15: 5500000781 | D15: 45320 | E15: 557809 | F15: =IFERROR(VLOOKUP(Table1[[#This Row],[Part Number]],DATABASE_FG!$C$6:D10004,2,FALSE)," ") -> ANLAUFSCHEIBE | G15: =IFERROR(_xlfn.XLOOKUP(Table1[[#This Row],[Part Number]],Table3[Part number],Table3[Drawing Revision]),"") -> e | H15: {=IFERROR(INDEX(PDB!$C:$AT,MATCH(E15,PDB!$B:$B,0),MATCH(YEAR(K15),0+PDB!$C$1:$AT$1,0)),"")} -> 10.79 | I15: 100 | J15: =IFERROR(Table1[[#This Row],[Quantity]]*Table1[[#This Row],[Price/Unit EUR]]," ") -> 1079 | K15: 45434 | L15: =WEEKNUM(Table1[[#This Row],[ETA As requested dd.mm.yyyy]]) -> 21 | M15: =YEAR(Table1[[#This Row],[ETA As requested dd.mm.yyyy]]) -> 2024 | N15: =IFERROR(INDEX(DATABASE_FG!$H$5:$H$367, MATCH(E15, DATABASE_FG!$C$5:$C$367, 0)), " ") -> 0 | O15: =IF(E15<>"", _xlfn.XLOOKUP(E15, DATABASE_FG!C:C, DATABASE_FG!F:F), " ") -> 0 | P15: =IFERROR(INDEX(DATABASE_FG!$G$5:$G$367, MATCH(E15, DATABASE_FG!$C$5:$C$367, 0)), "Not Found") -> 200 | R15: approved | S15: =IFERROR(INDEX(DATABASE_FG!$L$5:$L$367, MATCH(E15, DATABASE_FG!$C$5:$C$367, 0)), " ") -> 56 | T15: yes | Z15: 240609 | AA15: Yes | AB15: 45404 | AC15: 2024387 | AD15: =IF(NOT(ISBLANK(AC15)), C15, "") -> 5500000781 | AE15: =IF(NOT(ISBLANK(AC15)), E15, "") -> 557809 | AF15: 100 | AG15: =AF15*H15 -> 1079 | AJ15: 20240425-22.04.2025 | AK15: =IF(AB15="", IF(K15 < TODAY(), "Late", ""), IF(AB15 <= K15 + 2, "On Time", "Late")) -> On Time | AL15: =TEXT(K15,"mmmm") -> May | AM15: =YEAR(Table1[[#This Row],[ETA As requested dd.mm.yyyy]]) -> 2024
A16: Walterscheid | B16: firm | C16: 5500000781 | D16: 45320 | E16: 557809 | F16: =IFERROR(VLOOKUP(Table1[[#This Row],[Part Number]],DATABASE_FG!$C$6:D10005,2,FALSE)," ") -> ANLAUFSCHEIBE | G16: =IFERROR(_xlfn.XLOOKUP(Table1[[#This Row],[Part Number]],Table3[Part number],Table3[Drawing Revision]),"") -> e | H16: {=IFERROR(INDEX(PDB!$C:$AT,MATCH(E16,PDB!$B:$B,0),MATCH(YEAR(K16),0+PDB!$C$1:$AT$1,0)),"")} -> 10.79 | I16: 100 | J16: =IFERROR(Table1[[#This Row],[Quantity]]*Table1[[#This Row],[Price/Unit EUR]]," ") -> 1079 | K16: 45771 | L16: =WEEKNUM(Table1[[#This Row],[ETA As requested dd.mm.yyyy]]) -> 17 | M16: =YEAR(Table1[[#This Row],[ETA As requested dd.mm.yyyy]]) -> 2025 | N16: =IFERROR(INDEX(DATABASE_FG!$H$5:$H$367, MATCH(E16, DATABASE_FG!$C$5:$C$367, 0)), " ") -> 0 | P16: =IFERROR(INDEX(DATABASE_FG!$G$5:$G$367, MATCH(E16, DATABASE_FG!$C$5:$C$367, 0)), "Not Found") -> 200 | S16: =Table1[[#This Row],[Quantity]]/48 -> 2.0833333 | T16: yes | AA16: Yes | AB16: 45776 | AC16: 25687 | AD16: =IF(NOT(ISBLANK(AC16)), C16, "") -> 5500000781 | AE16: =IF(NOT(ISBLANK(AC16)), E16, "") -> 557809 | AF16: 100 | AG16: =AF16*H16 -> 1079 | AJ16: 20250565-29.04.2025 | AK16: =IF(AB16="", IF(K16 < TODAY(), "Late", ""), IF(AB16 <= K16 + 2, "On Time", "Late")) -> Late | AL16: =TEXT(K16,"mmmm") -> April | AM16: =YEAR(Table1[[#This Row],[ETA As requested dd.mm.yyyy]]) -> 2025
A17: Edwards | B17: firm | C17: 7018632237 | D17: 45125 | E17: 32166161 | F17: =IFERROR(VLOOKUP(Table1[[#This Row],[Part Number]],DATABASE_FG!$C$6:D10006,2,FALSE)," ") -> HV-ROTOR D8B PRE-MACHINED (6524466) | G17: =IFERROR(_xlfn.XLOOKUP(Table1[[#This Row],[Part Number]],Table3[Part number],Table3[Drawing Revision]),"") -> A1 | H17: {=IFERROR(INDEX(PDB!$C:$AT,MATCH(E17,PDB!$B:$B,0),MATCH(YEAR(K17),0+PDB!$C$1:$AT$1,0)),"")} | I17: 50 | J17: =IFERROR(Table1[[#This Row],[Quantity]]*Table1[[#This Row],[Price/Unit EUR]]," ") | K17: 45261 | L17: =WEEKNUM(Table1[[#This Row],[ETA As requested dd.mm.yyyy]]) -> 48 | M17: =YEAR(Table1[[#This Row],[ETA As requested dd.mm.yyyy]]) -> 2023 | N17: =IFERROR(INDEX(DATABASE_FG!$H$5:$H$367, MATCH(E17, DATABASE_FG!$C$5:$C$367, 0)), " ") -> 0 | O17: =IF(E17<>"", _xlfn.XLOOKUP(E17, DATABASE_FG!C:C, DATABASE_FG!F:F), " ") -> Rotor | P17: =IFERROR(INDEX(DATABASE_FG!$G$5:$G$367, MATCH(E17, DATABASE_FG!$C$5:$C$367, 0)), "Not Found") -> 50 | R17: project | S17: =IFERROR(INDEX(DATABASE_FG!$L$5:$L$367, MATCH(E17, DATABASE_FG!$C$5:$C$367, 0)), " ") -> 56 | T17: yes | AA17: Yes | AD17: =IF(NOT(ISBLANK(AC17)), C17, "") | AE17: =IF(NOT(ISBLANK(AC17)), E17, "") | AG17: =AF17*H17 -> #VALUE! | AI17: Proiect Anulat | AK17: =IF(AB17="", IF(K17 < TODAY(), "Late", ""), IF(AB17 <= K17 + 2, "On Time", "Late")) -> Late | AL17: =TEXT(K17,"mmmm") -> December | AM17: =YEAR(Table1[[#This Row],[ETA As requested dd.mm.yyyy]]) -> 2023
A18: Edwards | B18: firm | C18: 7018632237 | D18: 45125 | E18: 32166162 | F18: =IFERROR(VLOOKUP(Table1[[#This Row],[Part Number]],DATABASE_FG!$C$6:D10007,2,FALSE)," ") -> HV-ROTOR D16B PRE-MACHINED (6524201) | G18: =IFERROR(_xlfn.XLOOKUP(Table1[[#This Row],[Part Number]],Table3[Part number],Table3[Drawing Revision]),"") -> A0 | H18: {=IFERROR(INDEX(PDB!$C:$AT,MATCH(E18,PDB!$B:$B,0),MATCH(YEAR(K18),0+PDB!$C$1:$AT$1,0)),"")} | I18: 50 | J18: =IFERROR(Table1[[#This Row],[Quantity]]*Table1[[#This Row],[Price/Unit EUR]]," ") | K18: 45261 | L18: =WEEKNUM(Table1[[#This Row],[ETA As requested dd.mm.yyyy]]) -> 48 | M18: =YEAR(Table1[[#This Row],[ETA As requested dd.mm.yyyy]]) -> 2023 | N18: =IFERROR(INDEX(DATABASE_FG!$H$5:$H$367, MATCH(E18, DATABASE_FG!$C$5:$C$367, 0)), " ") -> 0 | O18: =IF(E18<>"", _xlfn.XLOOKUP(E18, DATABASE_FG!C:C, DATABASE_FG!F:F), " ") -> Rotor | P18: =IFERROR(INDEX(DATABASE_FG!$G$5:$G$367, MATCH(E18, DATABASE_FG!$C$5:$C$367, 0)), "Not Found") -> 50 | R18: project | S18: =IFERROR(INDEX(DATABASE_FG!$L$5:$L$367, MATCH(E18, DATABASE_FG!$C$5:$C$367, 0)), " ") -> 56 | T18: yes | AA18: Yes | AD18: =IF(NOT(ISBLANK(AC18)), C18, "") | AE18: =IF(NOT(ISBLANK(AC18)), E18, "") | AG18: =AF18*H18 -> #VALUE! | AI18: Proiect Anulat | AK18: =IF(AB18="", IF(K18 < TODAY(), "Late", ""), IF(AB18 <= K18 + 2, "On Time", "Late")) -> Late | AL18: =TEXT(K18,"mmmm") -> December | AM18: =YEAR(Table1[[#This Row],[ETA As requested dd.mm.yyyy]]) -> 2023
A19: BOSCH Homburg | B19: firm | C19: 4509573576 | D19: 45369 | E19: 1535100044 | F19: =IFERROR(VLOOKUP(Table1[[#This Row],[Part Number]],DATABASE_FG!$C$6:D10008,2,FALSE)," ") -> VALVE BODY . | G19: =IFERROR(_xlfn.XLOOKUP(Table1[[#This Row],[Part Number]],Table3[Part number],Table3[Drawing Revision]),"") -> AB | H19: {=IFERROR(INDEX(PDB!$C:$AT,MATCH(E19,PDB!$B:$B,0),MATCH(YEAR(K19),0+PDB!$C$1:$AT$1,0)),"")} -> 8.25 | I19: 509 | J19: =H19*I19 -> 4199.25 | K19: 45238 | L19: =WEEKNUM(Table1[[#This Row],[ETA As requested dd.mm.yyyy]]) -> 45 | M19: =YEAR(Table1[[#This Row],[ETA As requested dd.mm.yyyy]]) -> 2023 | N19: =IFERROR(INDEX(DATABASE_FG!$H$5:$H$367, MATCH(E19, DATABASE_FG!$C$5:$C$367, 0)), " ") -> 0 | O19: =IF(E19<>"", _xlfn.XLOOKUP(E19, DATABASE_FG!C:C, DATABASE_FG!F:F), " ") -> Ventilkoerper | P19: =IFERROR(INDEX(DATABASE_FG!$G$5:$G$367, MATCH(E19, DATABASE_FG!$C$5:$C$367, 0)), "Not Found") -> 550 | Q19: 60 | R19: approved | S19: =IFERROR(INDEX(DATABASE_FG!$L$5:$L$367, MATCH(E19, DATABASE_FG!$C$5:$C$367, 0)), " ") -> 56 | T19: yes | AA19: Yes | AB19: 45393 | AC19: 2024332 | AD19: =IF(NOT(ISBLANK(AC19)), C19, "") -> 4509573576 | AE19: =IF(NOT(ISBLANK(AC19)), E19, "") -> 1535100044 | AF19: 90 | AG19: =AF19*H19 -> 742.5 | AI19: livrata toata comanda, comanda inchisa in supplyon | AK19: =IF(AB19="", IF(K19 < TODAY(), "Late", ""), IF(AB19 <= K19 + 2, "On Time", "Late")) -> Late | AL19: =TEXT(K19,"mmmm") -> November | AM19: =YEAR(Table1[[#This Row],[ETA As requested dd.mm.yyyy]]) -> 2023
A20: BOSCH Homburg | B20: firm | C20: 5500495155 | D20: 45491 | E20: 1535100044 | F20: =IFERROR(VLOOKUP(Table1[[#This Row],[Part Number]],DATABASE_FG!$C$6:D10009,2,FALSE)," ") -> VALVE BODY . | G20: =IFERROR(_xlfn.XLOOKUP(Table1[[#This Row],[Part Number]],Table3[Part number],Table3[Drawing Revision]),"") -> AB | H20: {=IFERROR(INDEX(PDB!$C:$AT,MATCH(E20,PDB!$B:$B,0),MATCH(YEAR(K20),0+PDB!$C$1:$AT$1,0)),"")} -> 8.25 | I20: 5 | J20: =H20*I20 -> 41.25 | K20: 45403 | L20: =WEEKNUM(Table1[[#This Row],[ETA As requested dd.mm.yyyy]]) -> 17 | M20: =YEAR(Table1[[#This Row],[ETA As requested dd.mm.yyyy]]) -> 2024 | N20: =IFERROR(INDEX(DATABASE_FG!$H$5:$H$367, MATCH(E20, DATABASE_FG!$C$5:$C$367, 0)), " ") -> 0 | O20: =IF(E20<>"", _xlfn.XLOOKUP(E20, DATABASE_FG!C:C, DATABASE_FG!F:F), " ") -> Ventilkoerper | P20: =IFERROR(INDEX(DATABASE_FG!$G$5:$G$367, MATCH(E20, DATABASE_FG!$C$5:$C$367, 0)), "Not Found") -> 550 | Q20: 60 | R20: approved | S20: =IFERROR(INDEX(DATABASE_FG!$L$5:$L$367, MATCH(E20, DATABASE_FG!$C$5:$C$367, 0)), " ") -> 56 | T20: yes | Z20: 241307 | AA20: Yes | AB20: 45394 | AC20: 2024338 | AD20: =IF(NOT(ISBLANK(AC20)), C20, "") -> 5500495155 | AE20: =IF(NOT(ISBLANK(AC20)), E20, "") -> 1535100044 | AF20: 5 | AG20: =AF20*H20 -> 41.25 | AK20: =IF(AB20="", IF(K20 < TODAY(), "Late", ""), IF(AB20 <= K20 + 2, "On Time", "Late")) -> On Time | AL20: =TEXT(K20,"mmmm") -> April | AM20: =YEAR(Table1[[#This Row],[ETA As requested dd.mm.yyyy]]) -> 2024
A21: BOSCH Homburg | B21: firm | C21: 5500495155 | D21: 45491 | E21: 1535100044 | F21: =IFERROR(VLOOKUP(Table1[[#This Row],[Part Number]],DATABASE_FG!$C$6:D10010,2,FALSE)," ") -> VALVE BODY . | G21: =IFERROR(_xlfn.XLOOKUP(Table1[[#This Row],[Part Number]],Table3[Part number],Table3[Drawing Revision]),"") -> AB | H21: {=IFERROR(INDEX(PDB!$C:$AT,MATCH(E21,PDB!$B:$B,0),MATCH(YEAR(K21),0+PDB!$C$1:$AT$1,0)),"")} -> 8.25 | I21: 4 | J21: =H21*I21 -> 33 | K21: 45741 | L21: =WEEKNUM(Table1[[#This Row],[ETA As requested dd.mm.yyyy]]) -> 13 | M21: =YEAR(Table1[[#This Row],[ETA As requested dd.mm.yyyy]]) -> 2025 | N21: =IFERROR(INDEX(DATABASE_FG!$H$5:$H$367, MATCH(E21, DATABASE_FG!$C$5:$C$367, 0)), " ") -> 0 | O21: =IF(E21<>"", _xlfn.XLOOKUP(E21, DATABASE_FG!C:C, DATABASE_FG!F:F), " ") -> Ventilkoerper | P21: =IFERROR(INDEX(DATABASE_FG!$G$5:$G$367, MATCH(E21, DATABASE_FG!$C$5:$C$367, 0)), "Not Found") -> 550 | Q21: 60 | R21: approved | S21: =IFERROR(INDEX(DATABASE_FG!$L$5:$L$367, MATCH(E21, DATABASE_FG!$C$5:$C$367, 0)), " ") -> 56 | T21: yes | AA21: Yes | AB21: 45394 | AC21: 2024338 | AD21: =IF(NOT(ISBLANK(AC21)), C21, "") -> 5500495155 | AE21: =IF(NOT(ISBLANK(AC21)), E21, "") -> 1535100044 | AF21: 4 | AG21: =AF21*H21 -> 33 | AK21: =IF(AB21="", IF(K21 < TODAY(), "Late", ""), IF(AB21 <= K21 + 2, "On Time", "Late")) -> On Time | AL21: =TEXT(K21,"mmmm") -> March | AM21: =YEAR(Table1[[#This Row],[ETA As requested dd.mm.yyyy]]) -> 2025
A22: BOSCH Homburg | B22: firm | C22: 5500495155 | D22: 45749 | E22: 1535100044 | F22: =IFERROR(VLOOKUP(Table1[[#This Row],[Part Number]],DATABASE_FG!$C$6:D10011,2,FALSE)," ") -> VALVE BODY . | G22: =IFERROR(_xlfn.XLOOKUP(Table1[[#This Row],[Part Number]],Table3[Part number],Table3[Drawing Revision]),"") -> AB | H22: {=IFERROR(INDEX(PDB!$C:$AT,MATCH(E22,PDB!$B:$B,0),MATCH(YEAR(K22),0+PDB!$C$1:$AT$1,0)),"")} -> 8.25 | I22: 85 | J22: =IFERROR(Table1[[#This Row],[Quantity]]*Table1[[#This Row],[Price/Unit EUR]]," ") -> 701.25 | K22: 45789 | L22: =WEEKNUM(Table1[[#This Row],[ETA As requested dd.mm.yyyy]]) -> 20 | M22: =YEAR(Table1[[#This Row],[ETA As requested dd.mm.yyyy]]) -> 2025 | N22: =IFERROR(INDEX(DATABASE_FG!$H$5:$H$367, MATCH(E22, DATABASE_FG!$C$5:$C$367, 0)), " ") -> 0 | O22: =IF(E22<>"", _xlfn.XLOOKUP(E22, DATABASE_FG!C:C, DATABASE_FG!F:F), " ") -> Ventilkoerper | P22: =IFERROR(INDEX(DATABASE_FG!$G$5:$G$367, MATCH(E22, DATABASE_FG!$C$5:$C$367, 0)), "Not Found") -> 550 | Q22: 56 | R22: approved | S22: =IFERROR(INDEX(DATABASE_FG!$L$5:$L$367, MATCH(E22, DATABASE_FG!$C$5:$C$367, 0)), " ") -> 56 | T22: yes | W22: yes | Y22: produse | AA22: Yes | AB22: 45811 | AC22: 25868 | AD22: =IF(NOT(ISBLANK(AC22)), C22, "") -> 5500495155 | AE22: =IF(NOT(ISBLANK(AC22)), E22, "") -> 1535100044 | AF22: 85 | AG22: =AF22*H22 -> 701.25 | AJ22: 20250699-03.06.2025 | AK22: =IF(AB22="", IF(K22 < TODAY(), "Late", ""), IF(AB22 <= K22 + 2, "On Time", "Late")) -> Late | AL22: =TEXT(K22,"mmmm") -> May | AM22: =YEAR(Table1[[#This Row],[ETA As requested dd.mm.yyyy]]) -> 2025
A23: BOSCH Homburg | B23: firm | C23: 5500495155 | D23: 45749 | E23: 1535100044 | F23: =IFERROR(VLOOKUP(Table1[[#This Row],[Part Number]],DATABASE_FG!$C$6:D10012,2,FALSE)," ") -> VALVE BODY . | G23: =IFERROR(_xlfn.XLOOKUP(Table1[[#This Row],[Part Number]],Table3[Part number],Table3[Drawing Revision]),"") -> AB | H23: {=IFERROR(INDEX(PDB!$C:$AT,MATCH(E23,PDB!$B:$B,0),MATCH(YEAR(K23),0+PDB!$C$1:$AT$1,0)),"")} -> 8.25 | I23: =165+9 -> 174 | J23: =IFERROR(Table1[[#This Row],[Quantity]]*Table1[[#This Row],[Price/Unit EUR]]," ") -> 1435.5 | K23: 46006 | L23: =WEEKNUM(Table1[[#This Row],[ETA As requested dd.mm.yyyy]]) -> 51 | M23: =YEAR(Table1[[#This Row],[ETA As requested dd.mm.yyyy]]) -> 2025 | N23: =IFERROR(INDEX(DATABASE_FG!$H$5:$H$367, MATCH(E23, DATABASE_FG!$C$5:$C$367, 0)), " ") -> 0 | O23: =IF(E23<>"", _xlfn.XLOOKUP(E23, DATABASE_FG!C:C, DATABASE_FG!F:F), " ") -> Ventilkoerper | P23: =IFERROR(INDEX(DATABASE_FG!$G$5:$G$367, MATCH(E23, DATABASE_FG!$C$5:$C$367, 0)), "Not Found") -> 550 | Q23: 56 | R23: approved | S23: =IFERROR(INDEX(DATABASE_FG!$L$5:$L$367, MATCH(E23, DATABASE_FG!$C$5:$C$367, 0)), " ") -> 56 | T23: yes | AA23: Yes | AB23: 45859 | AC23: 251082 | AD23: =IF(NOT(ISBLANK(AC23)), C23, "") -> 5500495155 | AE23: =IF(NOT(ISBLANK(AC23)), E23, "") -> 1535100044 | AF23: 174 | AG23: =AF23*H23 -> 1435.5 | AJ23: 20250960-24.07.2025 | AK23: =IF(AB23="", IF(K23 < TODAY(), "Late", ""), IF(AB23 <= K23 + 2, "On Time", "Late")) -> On Time | AL23: =TEXT(K23,"mmmm") -> December | AM23: =YEAR(Table1[[#This Row],[ETA As requested dd.mm.yyyy]]) -> 2025
A24: BOSCH Homburg | B24: forecast | C24: 5500495155 | D24: 45749 | E24: 1535100044 | F24: =IFERROR(VLOOKUP(Table1[[#This Row],[Part Number]],DATABASE_FG!$C$6:D10013,2,FALSE)," ") -> VALVE BODY . | G24: =IFERROR(_xlfn.XLOOKUP(Table1[[#This Row],[Part Number]],Table3[Part number],Table3[Drawing Revision]),"") -> AB | H24: {=IFERROR(INDEX(PDB!$C:$AT,MATCH(E24,PDB!$B:$B,0),MATCH(YEAR(K24),0+PDB!$C$1:$AT$1,0)),"")} -> 0 | I24: =25-9 -> 16 | J24: =IFERROR(Table1[[#This Row],[Quantity]]*Table1[[#This Row],[Price/Unit EUR]]," ") -> 0 | K24: 46048 | L24: =WEEKNUM(Table1[[#This Row],[ETA As requested dd.mm.yyyy]]) -> 5 | M24: =YEAR(Table1[[#This Row],[ETA As requested dd.mm.yyyy]]) -> 2026 | N24: =IFERROR(INDEX(DATABASE_FG!$H$5:$H$367, MATCH(E24, DATABASE_FG!$C$5:$C$367, 0)), " ") -> 0 | O24: =IF(E24<>"", _xlfn.XLOOKUP(E24, DATABASE_FG!C:C, DATABASE_FG!F:F), " ") -> Ventilkoerper | P24: =IFERROR(INDEX(DATABASE_FG!$G$5:$G$367, MATCH(E24, DATABASE_FG!$C$5:$C$367, 0)), "Not Found") -> 550 | Q24: 56 | R24: approved | S24: =IFERROR(INDEX(DATABASE_FG!$L$5:$L$367, MATCH(E24, DATABASE_FG!$C$5:$C$367, 0)), " ") -> 56 | T24: yes | AA24: No | AD24: =IF(NOT(ISBLANK(AC24)), C24, "") | AE24: =IF(NOT(ISBLANK(AC24)), E24, "") | AG24: =AF24*H24 -> 0 | AK24: =IF(AB24="", IF(K24 < TODAY(), "Late", ""), IF(AB24 <= K24 + 2, "On Time", "Late")) | AL24: =TEXT(K24,"mmmm") -> January | AM24: =YEAR(Table1[[#This Row],[ETA As requested dd.mm.yyyy]]) -> 2026
A25: BOSCH Homburg | B25: forecast | C25: 5500495155 | D25: 45749 | E25: 1535100044 | F25: =IFERROR(VLOOKUP(Table1[[#This Row],[Part Number]],DATABASE_FG!$C$6:D10014,2,FALSE)," ") -> VALVE BODY . | G25: =IFERROR(_xlfn.XLOOKUP(Table1[[#This Row],[Part Number]],Table3[Part number],Table3[Drawing Revision]),"") -> AB | H25: {=IFERROR(INDEX(PDB!$C:$AT,MATCH(E25,PDB!$B:$B,0),MATCH(YEAR(K25),0+PDB!$C$1:$AT$1,0)),"")} -> 0 | I25: 15 | J25: =IFERROR(Table1[[#This Row],[Quantity]]*Table1[[#This Row],[Price/Unit EUR]]," ") -> 0 | K25: 46076 | L25: =WEEKNUM(Table1[[#This Row],[ETA As requested dd.mm.yyyy]]) -> 9 | M25: =YEAR(Table1[[#This Row],[ETA As requested dd.mm.yyyy]]) -> 2026 | N25: =IFERROR(INDEX(DATABASE_FG!$H$5:$H$367, MATCH(E25, DATABASE_FG!$C$5:$C$367, 0)), " ") -> 0 | O25: =IF(E25<>"", _xlfn.XLOOKUP(E25, DATABASE_FG!C:C, DATABASE_FG!F:F), " ") -> Ventilkoerper | P25: =IFERROR(INDEX(DATABASE_FG!$G$5:$G$367, MATCH(E25, DATABASE_FG!$C$5:$C$367, 0)), "Not Found") -> 550 | Q25: 56 | R25: approved | S25: =IFERROR(INDEX(DATABASE_FG!$L$5:$L$367, MATCH(E25, DATABASE_FG!$C$5:$C$367, 0)), " ") -> 56 | T25: yes | AA25: No | AD25: =IF(NOT(ISBLANK(AC25)), C25, "") | AE25: =IF(NOT(ISBLANK(AC25)), E25, "") | AG25: =AF25*H25 -> 0 | AK25: =IF(AB25="", IF(K25 < TODAY(), "Late", ""), IF(AB25 <= K25 + 2, "On Time", "Late")) | AL25: =TEXT(K25,"mmmm") -> February | AM25: =YEAR(Table1[[#This Row],[ETA As requested dd.mm.yyyy]]) -> 2026
A26: BOSCH Homburg | B26: forecast | C26: 5500495155 | D26: 45749 | E26: 1535100044 | F26: =IFERROR(VLOOKUP(Table1[[#This Row],[Part Number]],DATABASE_FG!$C$6:D10015,2,FALSE)," ") -> VALVE BODY . | G26: =IFERROR(_xlfn.XLOOKUP(Table1[[#This Row],[Part Number]],Table3[Part number],Table3[Drawing Revision]),"") -> AB | H26: {=IFERROR(INDEX(PDB!$C:$AT,MATCH(E26,PDB!$B:$B,0),MATCH(YEAR(K26),0+PDB!$C$1:$AT$1,0)),"")} -> 0 | I26: 45 | J26: =IFERROR(Table1[[#This Row],[Quantity]]*Table1[[#This Row],[Price/Unit EUR]]," ") -> 0 | K26: 46106 | L26: =WEEKNUM(Table1[[#This Row],[ETA As requested dd.mm.yyyy]]) -> 13 | M26: =YEAR(Table1[[#This Row],[ETA As requested dd.mm.yyyy]]) -> 2026 | N26: =IFERROR(INDEX(DATABASE_FG!$H$5:$H$367, MATCH(E26, DATABASE_FG!$C$5:$C$367, 0)), " ") -> 0 | O26: =IF(E26<>"", _xlfn.XLOOKUP(E26, DATABASE_FG!C:C, DATABASE_FG!F:F), " ") -> Ventilkoerper | P26: =IFERROR(INDEX(DATABASE_FG!$G$5:$G$367, MATCH(E26, DATABASE_FG!$C$5:$C$367, 0)), "Not Found") -> 550 | Q26: 56 | R26: approved | S26: =IFERROR(INDEX(DATABASE_FG!$L$5:$L$367, MATCH(E26, DATABASE_FG!$C$5:$C$367, 0)), " ") -> 56 | T26: yes | AA26: No | AD26: =IF(NOT(ISBLANK(AC26)), C26, "") | AE26: =IF(NOT(ISBLANK(AC26)), E26, "") | AG26: =AF26*H26 -> 0 | AK26: =IF(AB26="", IF(K26 < TODAY(), "Late", ""), IF(AB26 <= K26 + 2, "On Time", "Late")) | AL26: =TEXT(K26,"mmmm") -> March | AM26: =YEAR(Table1[[#This Row],[ETA As requested dd.mm.yyyy]]) -> 2026
A27: BOSCH Homburg | B27: forecast | C27: 5500495155 | D27: 45749 | E27: 1535100044 | F27: =IFERROR(VLOOKUP(Table1[[#This Row],[Part Number]],DATABASE_FG!$C$6:D10016,2,FALSE)," ") -> VALVE BODY . | G27: =IFERROR(_xlfn.XLOOKUP(Table1[[#This Row],[Part Number]],Table3[Part number],Table3[Drawing Revision]),"") -> AB | H27: {=IFERROR(INDEX(PDB!$C:$AT,MATCH(E27,PDB!$B:$B,0),MATCH(YEAR(K27),0+PDB!$C$1:$AT$1,0)),"")} -> 0 | I27: 30 | J27: =IFERROR(Table1[[#This Row],[Quantity]]*Table1[[#This Row],[Price/Unit EUR]]," ") -> 0 | K27: 46136 | L27: =WEEKNUM(Table1[[#This Row],[ETA As requested dd.mm.yyyy]]) -> 17 | M27: =YEAR(Table1[[#This Row],[ETA As requested dd.mm.yyyy]]) -> 2026 | N27: =IFERROR(INDEX(DATABASE_FG!$H$5:$H$367, MATCH(E27, DATABASE_FG!$C$5:$C$367, 0)), " ") -> 0 | O27: =IF(E27<>"", _xlfn.XLOOKUP(E27, DATABASE_FG!C:C, DATABASE_FG!F:F), " ") -> Ventilkoerper | P27: =IFERROR(INDEX(DATABASE_FG!$G$5:$G$367, MATCH(E27, DATABASE_FG!$C$5:$C$367, 0)), "Not Found") -> 550 | Q27: 56 | R27: approved | S27: =IFERROR(INDEX(DATABASE_FG!$L$5:$L$367, MATCH(E27, DATABASE_FG!$C$5:$C$367, 0)), " ") -> 56 | T27: yes | AA27: No | AD27: =IF(NOT(ISBLANK(AC27)), C27, "") | AE27: =IF(NOT(ISBLANK(AC27)), E27, "") | AG27: =AF27*H27 -> 0 | AK27: =IF(AB27="", IF(K27 < TODAY(), "Late", ""), IF(AB27 <= K27 + 2, "On Time", "Late")) | AL27: =TEXT(K27,"mmmm") -> April | AM27: =YEAR(Table1[[#This Row],[ETA As requested dd.mm.yyyy]]) -> 2026
A28: BOSCH Homburg | B28: forecast | C28: 5500495155 | D28: 45749 | E28: 1535100044 | F28: =IFERROR(VLOOKUP(Table1[[#This Row],[Part Number]],DATABASE_FG!$C$6:D10017,2,FALSE)," ") -> VALVE BODY . | G28: =IFERROR(_xlfn.XLOOKUP(Table1[[#This Row],[Part Number]],Table3[Part number],Table3[Drawing Revision]),"") -> AB | H28: {=IFERROR(INDEX(PDB!$C:$AT,MATCH(E28,PDB!$B:$B,0),MATCH(YEAR(K28),0+PDB!$C$1:$AT$1,0)),"")} -> 0 | I28: 35 | J28: =IFERROR(Table1[[#This Row],[Quantity]]*Table1[[#This Row],[Price/Unit EUR]]," ") -> 0 | K28: 46164 | L28: =WEEKNUM(Table1[[#This Row],[ETA As requested dd.mm.yyyy]]) -> 21 | M28: =YEAR(Table1[[#This Row],[ETA As requested dd.mm.yyyy]]) -> 2026 | N28: =IFERROR(INDEX(DATABASE_FG!$H$5:$H$367, MATCH(E28, DATABASE_FG!$C$5:$C$367, 0)), " ") -> 0 | O28: =IF(E28<>"", _xlfn.XLOOKUP(E28, DATABASE_FG!C:C, DATABASE_FG!F:F), " ") -> Ventilkoerper | P28: =IFERROR(INDEX(DATABASE_FG!$G$5:$G$367, MATCH(E28, DATABASE_FG!$C$5:$C$367, 0)), "Not Found") -> 550 | Q28: 56 | R28: approved | S28: =IFERROR(INDEX(DATABASE_FG!$L$5:$L$367, MATCH(E28, DATABASE_FG!$C$5:$C$367, 0)), " ") -> 56 | T28: yes | AA28: No | AD28: =IF(NOT(ISBLANK(AC28)), C28, "") | AE28: =IF(NOT(ISBLANK(AC28)), E28, "") | AG28: =AF28*H28 -> 0 | AK28: =IF(AB28="", IF(K28 < TODAY(), "Late", ""), IF(AB28 <= K28 + 2, "On Time", "Late")) | AL28: =TEXT(K28,"mmmm") -> May | AM28: =YEAR(Table1[[#This Row],[ETA As requested dd.mm.yyyy]]) -> 2026
